[2022-12-05T20:55:39.558+0000] {taskinstance.py:1165} INFO - Dependencies all met for <TaskInstance: dag.create_table manual__2022-12-05T20:55:37.806265+00:00 [queued]>
[2022-12-05T20:55:39.578+0000] {taskinstance.py:1165} INFO - Dependencies all met for <TaskInstance: dag.create_table manual__2022-12-05T20:55:37.806265+00:00 [queued]>
[2022-12-05T20:55:39.579+0000] {taskinstance.py:1362} INFO - 
--------------------------------------------------------------------------------
[2022-12-05T20:55:39.580+0000] {taskinstance.py:1363} INFO - Starting attempt 1 of 1
[2022-12-05T20:55:39.580+0000] {taskinstance.py:1364} INFO - 
--------------------------------------------------------------------------------
[2022-12-05T20:55:39.606+0000] {taskinstance.py:1383} INFO - Executing <Task(PostgresOperator): create_table> on 2022-12-05 20:55:37.806265+00:00
[2022-12-05T20:55:39.611+0000] {standard_task_runner.py:55} INFO - Started process 7183 to run task
[2022-12-05T20:55:39.616+0000] {standard_task_runner.py:82} INFO - Running: ['***', 'tasks', 'run', 'dag', 'create_table', 'manual__2022-12-05T20:55:37.806265+00:00', '--job-id', '948', '--raw', '--subdir', 'DAGS_FOLDER/dag.py', '--cfg-path', '/tmp/tmpgxeaaj51']
[2022-12-05T20:55:39.617+0000] {standard_task_runner.py:83} INFO - Job 948: Subtask create_table
[2022-12-05T20:55:39.711+0000] {task_command.py:376} INFO - Running <TaskInstance: dag.create_table manual__2022-12-05T20:55:37.806265+00:00 [running]> on host 02acd0b59b6f
[2022-12-05T20:55:39.839+0000] {taskinstance.py:1592} INFO - Exporting the following env vars:
AIRFLOW_CTX_DAG_OWNER=lofitravel
AIRFLOW_CTX_DAG_ID=dag
AIRFLOW_CTX_TASK_ID=create_table
AIRFLOW_CTX_EXECUTION_DATE=2022-12-05T20:55:37.806265+00:00
AIRFLOW_CTX_TRY_NUMBER=1
AIRFLOW_CTX_DAG_RUN_ID=manual__2022-12-05T20:55:37.806265+00:00
[2022-12-05T20:55:39.860+0000] {taskinstance.py:1851} ERROR - Task failed with exception
Traceback (most recent call last):
  File "/home/airflow/.local/lib/python3.7/site-packages/airflow/providers/postgres/operators/postgres.py", line 94, in execute
    self.hook.run(self.sql, self.autocommit, parameters=self.parameters)
  File "/home/airflow/.local/lib/python3.7/site-packages/airflow/providers/common/sql/hooks/sql.py", line 288, in run
    with closing(self.get_conn()) as conn:
  File "/home/airflow/.local/lib/python3.7/site-packages/airflow/providers/postgres/hooks/postgres.py", line 88, in get_conn
    conn = deepcopy(self.connection or self.get_connection(conn_id))
  File "/home/airflow/.local/lib/python3.7/site-packages/airflow/hooks/base.py", line 70, in get_connection
    conn = Connection.get_connection_from_secrets(conn_id)
  File "/home/airflow/.local/lib/python3.7/site-packages/airflow/models/connection.py", line 432, in get_connection_from_secrets
    raise AirflowNotFoundException(f"The conn_id `{conn_id}` isn't defined")
airflow.exceptions.AirflowNotFoundException: The conn_id `postgres_default` isn't defined
[2022-12-05T20:55:39.865+0000] {taskinstance.py:1406} INFO - Marking task as FAILED. dag_id=dag, task_id=create_table, execution_date=20221205T205537, start_date=20221205T205539, end_date=20221205T205539
[2022-12-05T20:55:39.883+0000] {standard_task_runner.py:105} ERROR - Failed to execute job 948 for task create_table (The conn_id `postgres_default` isn't defined; 7183)
[2022-12-05T20:55:39.907+0000] {local_task_job.py:159} INFO - Task exited with return code 1
[2022-12-05T20:55:39.928+0000] {taskinstance.py:2623} INFO - 0 downstream tasks scheduled from follow-on schedule check
