[2022-12-07T19:38:13.072+0000] {taskinstance.py:1165} INFO - Dependencies all met for <TaskInstance: dag.task_1_0 manual__2022-12-07T19:38:03.095285+00:00 [queued]>
[2022-12-07T19:38:13.164+0000] {taskinstance.py:1165} INFO - Dependencies all met for <TaskInstance: dag.task_1_0 manual__2022-12-07T19:38:03.095285+00:00 [queued]>
[2022-12-07T19:38:13.166+0000] {taskinstance.py:1362} INFO - 
--------------------------------------------------------------------------------
[2022-12-07T19:38:13.168+0000] {taskinstance.py:1363} INFO - Starting attempt 1 of 1
[2022-12-07T19:38:13.169+0000] {taskinstance.py:1364} INFO - 
--------------------------------------------------------------------------------
[2022-12-07T19:38:13.230+0000] {taskinstance.py:1383} INFO - Executing <Task(PythonOperator): task_1_0> on 2022-12-07 19:38:03.095285+00:00
[2022-12-07T19:38:13.249+0000] {standard_task_runner.py:55} INFO - Started process 6503 to run task
[2022-12-07T19:38:13.256+0000] {standard_task_runner.py:82} INFO - Running: ['***', 'tasks', 'run', 'dag', 'task_1_0', 'manual__2022-12-07T19:38:03.095285+00:00', '--job-id', '1901', '--raw', '--subdir', 'DAGS_FOLDER/dag.py', '--cfg-path', '/tmp/tmpzxr0fnjq']
[2022-12-07T19:38:13.258+0000] {standard_task_runner.py:83} INFO - Job 1901: Subtask task_1_0
[2022-12-07T19:38:13.596+0000] {task_command.py:376} INFO - Running <TaskInstance: dag.task_1_0 manual__2022-12-07T19:38:03.095285+00:00 [running]> on host a9d6893ff63e
[2022-12-07T19:38:14.033+0000] {taskinstance.py:1592} INFO - Exporting the following env vars:
AIRFLOW_CTX_DAG_OWNER=lofitravel
AIRFLOW_CTX_DAG_ID=dag
AIRFLOW_CTX_TASK_ID=task_1_0
AIRFLOW_CTX_EXECUTION_DATE=2022-12-07T19:38:03.095285+00:00
AIRFLOW_CTX_TRY_NUMBER=1
AIRFLOW_CTX_DAG_RUN_ID=manual__2022-12-07T19:38:03.095285+00:00
[2022-12-07T19:38:24.103+0000] {taskinstance.py:1851} ERROR - Task failed with exception
Traceback (most recent call last):
  File "/home/airflow/.local/lib/python3.7/site-packages/urllib3/connection.py", line 175, in _new_conn
    (self._dns_host, self.port), self.timeout, **extra_kw
  File "/home/airflow/.local/lib/python3.7/site-packages/urllib3/util/connection.py", line 72, in create_connection
    for res in socket.getaddrinfo(host, port, family, socket.SOCK_STREAM):
  File "/usr/local/lib/python3.7/socket.py", line 752, in getaddrinfo
    for res in _socket.getaddrinfo(host, port, family, type, proto, flags):
socket.gaierror: [Errno -3] Temporary failure in name resolution

During handling of the above exception, another exception occurred:

Traceback (most recent call last):
  File "/home/airflow/.local/lib/python3.7/site-packages/urllib3/connectionpool.py", line 710, in urlopen
    chunked=chunked,
  File "/home/airflow/.local/lib/python3.7/site-packages/urllib3/connectionpool.py", line 386, in _make_request
    self._validate_conn(conn)
  File "/home/airflow/.local/lib/python3.7/site-packages/urllib3/connectionpool.py", line 1042, in _validate_conn
    conn.connect()
  File "/home/airflow/.local/lib/python3.7/site-packages/urllib3/connection.py", line 358, in connect
    self.sock = conn = self._new_conn()
  File "/home/airflow/.local/lib/python3.7/site-packages/urllib3/connection.py", line 187, in _new_conn
    self, "Failed to establish a new connection: %s" % e
urllib3.exceptions.NewConnectionError: <urllib3.connection.HTTPSConnection object at 0x7fd9f9c6ce10>: Failed to establish a new connection: [Errno -3] Temporary failure in name resolution

During handling of the above exception, another exception occurred:

Traceback (most recent call last):
  File "/home/airflow/.local/lib/python3.7/site-packages/requests/adapters.py", line 499, in send
    timeout=timeout,
  File "/home/airflow/.local/lib/python3.7/site-packages/urllib3/connectionpool.py", line 788, in urlopen
    method, url, error=e, _pool=self, _stacktrace=sys.exc_info()[2]
  File "/home/airflow/.local/lib/python3.7/site-packages/urllib3/util/retry.py", line 592, in increment
    raise MaxRetryError(_pool, url, error or ResponseError(cause))
urllib3.exceptions.MaxRetryError: HTTPSConnectionPool(host='api.currencybeacon.com', port=443): Max retries exceeded with url: /v1/convert?api_key=82adcbbbae7a13d16e0b68fa1f50c023&from=EUR&to=RUB&amount=1 (Caused by NewConnectionError('<urllib3.connection.HTTPSConnection object at 0x7fd9f9c6ce10>: Failed to establish a new connection: [Errno -3] Temporary failure in name resolution'))

During handling of the above exception, another exception occurred:

Traceback (most recent call last):
  File "/home/airflow/.local/lib/python3.7/site-packages/airflow/operators/python.py", line 175, in execute
    return_value = self.execute_callable()
  File "/home/airflow/.local/lib/python3.7/site-packages/airflow/operators/python.py", line 193, in execute_callable
    return self.python_callable(*self.op_args, **self.op_kwargs)
  File "/opt/airflow/dags/dag.py", line 25, in get_currencies_task
    value = obj.pair(ticker_from, ticker_to)#....#
  File "/opt/airflow/dags/dag.py", line 88, in pair
    response =  requests.get('https://api.currencybeacon.com/v1/convert', params={'api_key': TOKEN, 'from': ticker_from, 'to': ticker_to, 'amount': 1})
  File "/home/airflow/.local/lib/python3.7/site-packages/requests/api.py", line 73, in get
    return request("get", url, params=params, **kwargs)
  File "/home/airflow/.local/lib/python3.7/site-packages/requests/api.py", line 59, in request
    return session.request(method=method, url=url, **kwargs)
  File "/home/airflow/.local/lib/python3.7/site-packages/requests/sessions.py", line 587, in request
    resp = self.send(prep, **send_kwargs)
  File "/home/airflow/.local/lib/python3.7/site-packages/requests/sessions.py", line 701, in send
    r = adapter.send(request, **kwargs)
  File "/home/airflow/.local/lib/python3.7/site-packages/requests/adapters.py", line 565, in send
    raise ConnectionError(e, request=request)
requests.exceptions.ConnectionError: HTTPSConnectionPool(host='api.currencybeacon.com', port=443): Max retries exceeded with url: /v1/convert?api_key=82adcbbbae7a13d16e0b68fa1f50c023&from=EUR&to=RUB&amount=1 (Caused by NewConnectionError('<urllib3.connection.HTTPSConnection object at 0x7fd9f9c6ce10>: Failed to establish a new connection: [Errno -3] Temporary failure in name resolution'))
[2022-12-07T19:38:24.180+0000] {taskinstance.py:1406} INFO - Marking task as FAILED. dag_id=dag, task_id=task_1_0, execution_date=20221207T193803, start_date=20221207T193813, end_date=20221207T193824
[2022-12-07T19:38:24.283+0000] {standard_task_runner.py:105} ERROR - Failed to execute job 1901 for task task_1_0 (HTTPSConnectionPool(host='api.currencybeacon.com', port=443): Max retries exceeded with url: /v1/convert?api_key=82adcbbbae7a13d16e0b68fa1f50c023&from=EUR&to=RUB&amount=1 (Caused by NewConnectionError('<urllib3.connection.HTTPSConnection object at 0x7fd9f9c6ce10>: Failed to establish a new connection: [Errno -3] Temporary failure in name resolution')); 6503)
[2022-12-07T19:38:24.394+0000] {local_task_job.py:159} INFO - Task exited with return code 1
[2022-12-07T19:38:24.604+0000] {taskinstance.py:2623} INFO - 0 downstream tasks scheduled from follow-on schedule check
