[2022-12-05T21:46:56.704+0000] {taskinstance.py:1165} INFO - Dependencies all met for <TaskInstance: dag.create_table manual__2022-12-05T21:46:52.592573+00:00 [queued]>
[2022-12-05T21:46:56.737+0000] {taskinstance.py:1165} INFO - Dependencies all met for <TaskInstance: dag.create_table manual__2022-12-05T21:46:52.592573+00:00 [queued]>
[2022-12-05T21:46:56.739+0000] {taskinstance.py:1362} INFO - 
--------------------------------------------------------------------------------
[2022-12-05T21:46:56.740+0000] {taskinstance.py:1363} INFO - Starting attempt 1 of 1
[2022-12-05T21:46:56.741+0000] {taskinstance.py:1364} INFO - 
--------------------------------------------------------------------------------
[2022-12-05T21:46:56.841+0000] {taskinstance.py:1383} INFO - Executing <Task(PostgresOperator): create_table> on 2022-12-05 21:46:52.592573+00:00
[2022-12-05T21:46:56.852+0000] {standard_task_runner.py:55} INFO - Started process 1909 to run task
[2022-12-05T21:46:56.863+0000] {standard_task_runner.py:82} INFO - Running: ['***', 'tasks', 'run', 'dag', 'create_table', 'manual__2022-12-05T21:46:52.592573+00:00', '--job-id', '976', '--raw', '--subdir', 'DAGS_FOLDER/dag.py', '--cfg-path', '/tmp/tmp919dxpaf']
[2022-12-05T21:46:56.866+0000] {standard_task_runner.py:83} INFO - Job 976: Subtask create_table
[2022-12-05T21:46:57.186+0000] {task_command.py:376} INFO - Running <TaskInstance: dag.create_table manual__2022-12-05T21:46:52.592573+00:00 [running]> on host cd03d50e9713
[2022-12-05T21:46:57.636+0000] {taskinstance.py:1592} INFO - Exporting the following env vars:
AIRFLOW_CTX_DAG_OWNER=lofitravel
AIRFLOW_CTX_DAG_ID=dag
AIRFLOW_CTX_TASK_ID=create_table
AIRFLOW_CTX_EXECUTION_DATE=2022-12-05T21:46:52.592573+00:00
AIRFLOW_CTX_TRY_NUMBER=1
AIRFLOW_CTX_DAG_RUN_ID=manual__2022-12-05T21:46:52.592573+00:00
[2022-12-05T21:46:57.680+0000] {base.py:71} INFO - Using connection ID 'postgres_localhost' for task execution.
[2022-12-05T21:46:57.700+0000] {taskinstance.py:1851} ERROR - Task failed with exception
Traceback (most recent call last):
  File "/home/airflow/.local/lib/python3.7/site-packages/airflow/providers/postgres/operators/postgres.py", line 94, in execute
    self.hook.run(self.sql, self.autocommit, parameters=self.parameters)
  File "/home/airflow/.local/lib/python3.7/site-packages/airflow/providers/common/sql/hooks/sql.py", line 288, in run
    with closing(self.get_conn()) as conn:
  File "/home/airflow/.local/lib/python3.7/site-packages/airflow/providers/postgres/hooks/postgres.py", line 115, in get_conn
    self.conn = psycopg2.connect(**conn_args)
  File "/home/airflow/.local/lib/python3.7/site-packages/psycopg2/__init__.py", line 122, in connect
    conn = _connect(dsn, connection_factory=connection_factory, **kwasync)
psycopg2.OperationalError: connection to server at "localhost" (127.0.0.1), port 5432 failed: Connection refused
	Is the server running on that host and accepting TCP/IP connections?
connection to server at "localhost" (::1), port 5432 failed: Cannot assign requested address
	Is the server running on that host and accepting TCP/IP connections?

[2022-12-05T21:46:57.763+0000] {taskinstance.py:1406} INFO - Marking task as FAILED. dag_id=dag, task_id=create_table, execution_date=20221205T214652, start_date=20221205T214656, end_date=20221205T214657
[2022-12-05T21:46:57.869+0000] {standard_task_runner.py:105} ERROR - Failed to execute job 976 for task create_table (connection to server at "localhost" (127.0.0.1), port 5432 failed: Connection refused
	Is the server running on that host and accepting TCP/IP connections?
connection to server at "localhost" (::1), port 5432 failed: Cannot assign requested address
	Is the server running on that host and accepting TCP/IP connections?
; 1909)
[2022-12-05T21:46:57.975+0000] {local_task_job.py:159} INFO - Task exited with return code 1
[2022-12-05T21:46:58.085+0000] {taskinstance.py:2623} INFO - 0 downstream tasks scheduled from follow-on schedule check
