[2022-12-05T20:12:22.171+0000] {taskinstance.py:1165} INFO - Dependencies all met for <TaskInstance: dag.task_0_0 manual__2022-12-05T20:12:20.683258+00:00 [queued]>
[2022-12-05T20:12:22.207+0000] {taskinstance.py:1165} INFO - Dependencies all met for <TaskInstance: dag.task_0_0 manual__2022-12-05T20:12:20.683258+00:00 [queued]>
[2022-12-05T20:12:22.208+0000] {taskinstance.py:1362} INFO - 
--------------------------------------------------------------------------------
[2022-12-05T20:12:22.209+0000] {taskinstance.py:1363} INFO - Starting attempt 1 of 1
[2022-12-05T20:12:22.211+0000] {taskinstance.py:1364} INFO - 
--------------------------------------------------------------------------------
[2022-12-05T20:12:22.257+0000] {taskinstance.py:1383} INFO - Executing <Task(PythonOperator): task_0_0> on 2022-12-05 20:12:20.683258+00:00
[2022-12-05T20:12:22.266+0000] {standard_task_runner.py:55} INFO - Started process 5194 to run task
[2022-12-05T20:12:22.273+0000] {standard_task_runner.py:82} INFO - Running: ['***', 'tasks', 'run', 'dag', 'task_0_0', 'manual__2022-12-05T20:12:20.683258+00:00', '--job-id', '923', '--raw', '--subdir', 'DAGS_FOLDER/dag.py', '--cfg-path', '/tmp/tmpyxhsu98j']
[2022-12-05T20:12:22.274+0000] {standard_task_runner.py:83} INFO - Job 923: Subtask task_0_0
[2022-12-05T20:12:22.448+0000] {task_command.py:376} INFO - Running <TaskInstance: dag.task_0_0 manual__2022-12-05T20:12:20.683258+00:00 [running]> on host 02acd0b59b6f
[2022-12-05T20:12:22.595+0000] {taskinstance.py:1592} INFO - Exporting the following env vars:
AIRFLOW_CTX_DAG_OWNER=lofitravel
AIRFLOW_CTX_DAG_ID=dag
AIRFLOW_CTX_TASK_ID=task_0_0
AIRFLOW_CTX_EXECUTION_DATE=2022-12-05T20:12:20.683258+00:00
AIRFLOW_CTX_TRY_NUMBER=1
AIRFLOW_CTX_DAG_RUN_ID=manual__2022-12-05T20:12:20.683258+00:00
[2022-12-05T20:12:22.596+0000] {taskinstance.py:1851} ERROR - Task failed with exception
Traceback (most recent call last):
  File "/home/airflow/.local/lib/python3.7/site-packages/airflow/operators/python.py", line 173, in execute
    self.op_kwargs = self.determine_kwargs(context)
  File "/home/airflow/.local/lib/python3.7/site-packages/airflow/operators/python.py", line 184, in determine_kwargs
    return KeywordParameters.determine(self.python_callable, self.op_args, context).unpacking()
  File "/home/airflow/.local/lib/python3.7/site-packages/airflow/utils/operator_helpers.py", line 161, in determine
    raise ValueError(f"The key {name!r} in args is a part of kwargs and therefore reserved.")
ValueError: The key 'ti' in args is a part of kwargs and therefore reserved.
[2022-12-05T20:12:22.612+0000] {taskinstance.py:1406} INFO - Marking task as FAILED. dag_id=dag, task_id=task_0_0, execution_date=20221205T201220, start_date=20221205T201222, end_date=20221205T201222
[2022-12-05T20:12:22.638+0000] {standard_task_runner.py:105} ERROR - Failed to execute job 923 for task task_0_0 (The key 'ti' in args is a part of kwargs and therefore reserved.; 5194)
[2022-12-05T20:12:22.687+0000] {local_task_job.py:159} INFO - Task exited with return code 1
[2022-12-05T20:12:22.731+0000] {taskinstance.py:2623} INFO - 0 downstream tasks scheduled from follow-on schedule check
