[2022-12-06T22:03:44.675+0000] {taskinstance.py:1165} INFO - Dependencies all met for <TaskInstance: dag.create_table manual__2022-12-06T22:03:40.506740+00:00 [queued]>
[2022-12-06T22:03:44.688+0000] {taskinstance.py:1165} INFO - Dependencies all met for <TaskInstance: dag.create_table manual__2022-12-06T22:03:40.506740+00:00 [queued]>
[2022-12-06T22:03:44.689+0000] {taskinstance.py:1362} INFO - 
--------------------------------------------------------------------------------
[2022-12-06T22:03:44.689+0000] {taskinstance.py:1363} INFO - Starting attempt 1 of 1
[2022-12-06T22:03:44.690+0000] {taskinstance.py:1364} INFO - 
--------------------------------------------------------------------------------
[2022-12-06T22:03:44.707+0000] {taskinstance.py:1383} INFO - Executing <Task(PostgresOperator): create_table> on 2022-12-06 22:03:40.506740+00:00
[2022-12-06T22:03:44.712+0000] {standard_task_runner.py:55} INFO - Started process 1661 to run task
[2022-12-06T22:03:44.716+0000] {standard_task_runner.py:82} INFO - Running: ['***', 'tasks', 'run', 'dag', 'create_table', 'manual__2022-12-06T22:03:40.506740+00:00', '--job-id', '1174', '--raw', '--subdir', 'DAGS_FOLDER/dag.py', '--cfg-path', '/tmp/tmpl81hdnuy']
[2022-12-06T22:03:44.717+0000] {standard_task_runner.py:83} INFO - Job 1174: Subtask create_table
[2022-12-06T22:03:44.792+0000] {task_command.py:376} INFO - Running <TaskInstance: dag.create_table manual__2022-12-06T22:03:40.506740+00:00 [running]> on host 505aa50095aa
[2022-12-06T22:03:44.893+0000] {taskinstance.py:1592} INFO - Exporting the following env vars:
AIRFLOW_CTX_DAG_OWNER=lofitravel
AIRFLOW_CTX_DAG_ID=dag
AIRFLOW_CTX_TASK_ID=create_table
AIRFLOW_CTX_EXECUTION_DATE=2022-12-06T22:03:40.506740+00:00
AIRFLOW_CTX_TRY_NUMBER=1
AIRFLOW_CTX_DAG_RUN_ID=manual__2022-12-06T22:03:40.506740+00:00
[2022-12-06T22:03:44.909+0000] {base.py:71} INFO - Using connection ID 'postgres_localhost' for task execution.
[2022-12-06T22:03:44.921+0000] {taskinstance.py:1851} ERROR - Task failed with exception
Traceback (most recent call last):
  File "/home/airflow/.local/lib/python3.7/site-packages/airflow/providers/postgres/operators/postgres.py", line 94, in execute
    self.hook.run(self.sql, self.autocommit, parameters=self.parameters)
  File "/home/airflow/.local/lib/python3.7/site-packages/airflow/providers/common/sql/hooks/sql.py", line 288, in run
    with closing(self.get_conn()) as conn:
  File "/home/airflow/.local/lib/python3.7/site-packages/airflow/providers/postgres/hooks/postgres.py", line 115, in get_conn
    self.conn = psycopg2.connect(**conn_args)
  File "/home/airflow/.local/lib/python3.7/site-packages/psycopg2/__init__.py", line 122, in connect
    conn = _connect(dsn, connection_factory=connection_factory, **kwasync)
psycopg2.OperationalError: connection to server at "database" (172.21.0.4), port 5432 failed: FATAL:  database "test" does not exist

[2022-12-06T22:03:44.938+0000] {taskinstance.py:1406} INFO - Marking task as FAILED. dag_id=dag, task_id=create_table, execution_date=20221206T220340, start_date=20221206T220344, end_date=20221206T220344
[2022-12-06T22:03:44.963+0000] {standard_task_runner.py:105} ERROR - Failed to execute job 1174 for task create_table (connection to server at "database" (172.21.0.4), port 5432 failed: FATAL:  database "test" does not exist
; 1661)
[2022-12-06T22:03:45.009+0000] {local_task_job.py:159} INFO - Task exited with return code 1
[2022-12-06T22:03:45.062+0000] {taskinstance.py:2623} INFO - 0 downstream tasks scheduled from follow-on schedule check
