[2022-12-07T07:41:42.067+0000] {taskinstance.py:1165} INFO - Dependencies all met for <TaskInstance: dag.create_table manual__2022-12-07T07:41:37.554705+00:00 [queued]>
[2022-12-07T07:41:42.080+0000] {taskinstance.py:1165} INFO - Dependencies all met for <TaskInstance: dag.create_table manual__2022-12-07T07:41:37.554705+00:00 [queued]>
[2022-12-07T07:41:42.081+0000] {taskinstance.py:1362} INFO - 
--------------------------------------------------------------------------------
[2022-12-07T07:41:42.081+0000] {taskinstance.py:1363} INFO - Starting attempt 1 of 1
[2022-12-07T07:41:42.082+0000] {taskinstance.py:1364} INFO - 
--------------------------------------------------------------------------------
[2022-12-07T07:41:42.099+0000] {taskinstance.py:1383} INFO - Executing <Task(PostgresOperator): create_table> on 2022-12-07 07:41:37.554705+00:00
[2022-12-07T07:41:42.103+0000] {standard_task_runner.py:55} INFO - Started process 29199 to run task
[2022-12-07T07:41:42.107+0000] {standard_task_runner.py:82} INFO - Running: ['***', 'tasks', 'run', 'dag', 'create_table', 'manual__2022-12-07T07:41:37.554705+00:00', '--job-id', '1525', '--raw', '--subdir', 'DAGS_FOLDER/dag.py', '--cfg-path', '/tmp/tmpcge61dei']
[2022-12-07T07:41:42.108+0000] {standard_task_runner.py:83} INFO - Job 1525: Subtask create_table
[2022-12-07T07:41:42.186+0000] {task_command.py:376} INFO - Running <TaskInstance: dag.create_table manual__2022-12-07T07:41:37.554705+00:00 [running]> on host 505aa50095aa
[2022-12-07T07:41:42.274+0000] {taskinstance.py:1592} INFO - Exporting the following env vars:
AIRFLOW_CTX_DAG_OWNER=lofitravel
AIRFLOW_CTX_DAG_ID=dag
AIRFLOW_CTX_TASK_ID=create_table
AIRFLOW_CTX_EXECUTION_DATE=2022-12-07T07:41:37.554705+00:00
AIRFLOW_CTX_TRY_NUMBER=1
AIRFLOW_CTX_DAG_RUN_ID=manual__2022-12-07T07:41:37.554705+00:00
[2022-12-07T07:41:42.287+0000] {base.py:71} INFO - Using connection ID 'postgres_localhost' for task execution.
[2022-12-07T07:41:42.299+0000] {sql.py:315} INFO - Running statement: 
        CREATE TABLE IF NOT EXISTS pairs(
            date TIMESTAMP,
            ticker_from VARCHAR(3),
            ticker_to VARCHAR(3),
            ticker_to VARCHAR(39));
        , parameters: None
[2022-12-07T07:41:42.301+0000] {taskinstance.py:1851} ERROR - Task failed with exception
Traceback (most recent call last):
  File "/home/airflow/.local/lib/python3.7/site-packages/airflow/providers/postgres/operators/postgres.py", line 94, in execute
    self.hook.run(self.sql, self.autocommit, parameters=self.parameters)
  File "/home/airflow/.local/lib/python3.7/site-packages/airflow/providers/common/sql/hooks/sql.py", line 295, in run
    self._run_command(cur, sql_statement, parameters)
  File "/home/airflow/.local/lib/python3.7/site-packages/airflow/providers/common/sql/hooks/sql.py", line 320, in _run_command
    cur.execute(sql_statement)
psycopg2.errors.DuplicateColumn: column "ticker_to" specified more than once

[2022-12-07T07:41:42.316+0000] {taskinstance.py:1406} INFO - Marking task as FAILED. dag_id=dag, task_id=create_table, execution_date=20221207T074137, start_date=20221207T074142, end_date=20221207T074142
[2022-12-07T07:41:42.332+0000] {standard_task_runner.py:105} ERROR - Failed to execute job 1525 for task create_table (column "ticker_to" specified more than once
; 29199)
[2022-12-07T07:41:42.359+0000] {local_task_job.py:159} INFO - Task exited with return code 1
[2022-12-07T07:41:42.395+0000] {taskinstance.py:2623} INFO - 0 downstream tasks scheduled from follow-on schedule check
