[2022-12-06T19:11:10.448+0000] {taskinstance.py:1165} INFO - Dependencies all met for <TaskInstance: dag.pull_data manual__2022-12-06T19:11:07.554969+00:00 [queued]>
[2022-12-06T19:11:10.477+0000] {taskinstance.py:1165} INFO - Dependencies all met for <TaskInstance: dag.pull_data manual__2022-12-06T19:11:07.554969+00:00 [queued]>
[2022-12-06T19:11:10.479+0000] {taskinstance.py:1362} INFO - 
--------------------------------------------------------------------------------
[2022-12-06T19:11:10.481+0000] {taskinstance.py:1363} INFO - Starting attempt 1 of 1
[2022-12-06T19:11:10.483+0000] {taskinstance.py:1364} INFO - 
--------------------------------------------------------------------------------
[2022-12-06T19:11:10.527+0000] {taskinstance.py:1383} INFO - Executing <Task(PythonOperator): pull_data> on 2022-12-06 19:11:07.554969+00:00
[2022-12-06T19:11:10.539+0000] {standard_task_runner.py:55} INFO - Started process 2398 to run task
[2022-12-06T19:11:10.562+0000] {standard_task_runner.py:82} INFO - Running: ['***', 'tasks', 'run', 'dag', 'pull_data', 'manual__2022-12-06T19:11:07.554969+00:00', '--job-id', '1048', '--raw', '--subdir', 'DAGS_FOLDER/dag.py', '--cfg-path', '/tmp/tmpms0u4pos']
[2022-12-06T19:11:10.563+0000] {standard_task_runner.py:83} INFO - Job 1048: Subtask pull_data
[2022-12-06T19:11:10.744+0000] {task_command.py:376} INFO - Running <TaskInstance: dag.pull_data manual__2022-12-06T19:11:07.554969+00:00 [running]> on host f1257ac346c8
[2022-12-06T19:11:10.969+0000] {taskinstance.py:1592} INFO - Exporting the following env vars:
AIRFLOW_CTX_DAG_OWNER=lofitravel
AIRFLOW_CTX_DAG_ID=dag
AIRFLOW_CTX_TASK_ID=pull_data
AIRFLOW_CTX_EXECUTION_DATE=2022-12-06T19:11:07.554969+00:00
AIRFLOW_CTX_TRY_NUMBER=1
AIRFLOW_CTX_DAG_RUN_ID=manual__2022-12-06T19:11:07.554969+00:00
[2022-12-06T19:11:10.971+0000] {taskinstance.py:1851} ERROR - Task failed with exception
Traceback (most recent call last):
  File "/home/airflow/.local/lib/python3.7/site-packages/airflow/operators/python.py", line 175, in execute
    return_value = self.execute_callable()
  File "/home/airflow/.local/lib/python3.7/site-packages/airflow/operators/python.py", line 193, in execute_callable
    return self.python_callable(*self.op_args, **self.op_kwargs)
  File "/opt/airflow/dags/dag.py", line 21, in pull_data
    list_of_values = ti.xcom_pull(key='value', task_id=task_list)
  File "/home/airflow/.local/lib/python3.7/site-packages/airflow/utils/session.py", line 75, in wrapper
    return func(*args, session=session, **kwargs)
TypeError: xcom_pull() got an unexpected keyword argument 'task_id'
[2022-12-06T19:11:11.029+0000] {taskinstance.py:1406} INFO - Marking task as FAILED. dag_id=dag, task_id=pull_data, execution_date=20221206T191107, start_date=20221206T191110, end_date=20221206T191111
[2022-12-06T19:11:11.073+0000] {standard_task_runner.py:105} ERROR - Failed to execute job 1048 for task pull_data (xcom_pull() got an unexpected keyword argument 'task_id'; 2398)
[2022-12-06T19:11:11.106+0000] {local_task_job.py:159} INFO - Task exited with return code 1
[2022-12-06T19:11:11.173+0000] {taskinstance.py:2623} INFO - 0 downstream tasks scheduled from follow-on schedule check
