[2022-12-07T23:52:47.734+0000] {taskinstance.py:1165} INFO - Dependencies all met for <TaskInstance: dag.create_table manual__2022-12-07T23:52:40.101453+00:00 [queued]>
[2022-12-07T23:52:47.751+0000] {taskinstance.py:1165} INFO - Dependencies all met for <TaskInstance: dag.create_table manual__2022-12-07T23:52:40.101453+00:00 [queued]>
[2022-12-07T23:52:47.752+0000] {taskinstance.py:1362} INFO - 
--------------------------------------------------------------------------------
[2022-12-07T23:52:47.753+0000] {taskinstance.py:1363} INFO - Starting attempt 1 of 1
[2022-12-07T23:52:47.753+0000] {taskinstance.py:1364} INFO - 
--------------------------------------------------------------------------------
[2022-12-07T23:52:47.773+0000] {taskinstance.py:1383} INFO - Executing <Task(PostgresOperator): create_table> on 2022-12-07 23:52:40.101453+00:00
[2022-12-07T23:52:47.779+0000] {standard_task_runner.py:55} INFO - Started process 429 to run task
[2022-12-07T23:52:47.783+0000] {standard_task_runner.py:82} INFO - Running: ['***', 'tasks', 'run', 'dag', 'create_table', 'manual__2022-12-07T23:52:40.101453+00:00', '--job-id', '19', '--raw', '--subdir', 'DAGS_FOLDER/dag.py', '--cfg-path', '/tmp/tmpqadgfoiv']
[2022-12-07T23:52:47.784+0000] {standard_task_runner.py:83} INFO - Job 19: Subtask create_table
[2022-12-07T23:52:47.888+0000] {task_command.py:376} INFO - Running <TaskInstance: dag.create_table manual__2022-12-07T23:52:40.101453+00:00 [running]> on host 564356c68f54
[2022-12-07T23:52:47.991+0000] {taskinstance.py:1592} INFO - Exporting the following env vars:
AIRFLOW_CTX_DAG_OWNER=lofitravel
AIRFLOW_CTX_DAG_ID=dag
AIRFLOW_CTX_TASK_ID=create_table
AIRFLOW_CTX_EXECUTION_DATE=2022-12-07T23:52:40.101453+00:00
AIRFLOW_CTX_TRY_NUMBER=1
AIRFLOW_CTX_DAG_RUN_ID=manual__2022-12-07T23:52:40.101453+00:00
[2022-12-07T23:52:48.013+0000] {taskinstance.py:1851} ERROR - Task failed with exception
Traceback (most recent call last):
  File "/home/airflow/.local/lib/python3.7/site-packages/airflow/providers/postgres/operators/postgres.py", line 94, in execute
    self.hook.run(self.sql, self.autocommit, parameters=self.parameters)
  File "/home/airflow/.local/lib/python3.7/site-packages/airflow/providers/common/sql/hooks/sql.py", line 288, in run
    with closing(self.get_conn()) as conn:
  File "/home/airflow/.local/lib/python3.7/site-packages/airflow/providers/postgres/hooks/postgres.py", line 88, in get_conn
    conn = deepcopy(self.connection or self.get_connection(conn_id))
  File "/home/airflow/.local/lib/python3.7/site-packages/airflow/hooks/base.py", line 70, in get_connection
    conn = Connection.get_connection_from_secrets(conn_id)
  File "/home/airflow/.local/lib/python3.7/site-packages/airflow/models/connection.py", line 432, in get_connection_from_secrets
    raise AirflowNotFoundException(f"The conn_id `{conn_id}` isn't defined")
airflow.exceptions.AirflowNotFoundException: The conn_id `postgres_localhost` isn't defined
[2022-12-07T23:52:48.018+0000] {taskinstance.py:1406} INFO - Marking task as FAILED. dag_id=dag, task_id=create_table, execution_date=20221207T235240, start_date=20221207T235247, end_date=20221207T235248
[2022-12-07T23:52:48.033+0000] {standard_task_runner.py:105} ERROR - Failed to execute job 19 for task create_table (The conn_id `postgres_localhost` isn't defined; 429)
[2022-12-07T23:52:48.076+0000] {local_task_job.py:159} INFO - Task exited with return code 1
[2022-12-07T23:52:48.110+0000] {taskinstance.py:2623} INFO - 0 downstream tasks scheduled from follow-on schedule check
