[2022-12-07T10:33:08.491+0000] {taskinstance.py:1165} INFO - Dependencies all met for <TaskInstance: dag.task_1_0 manual__2022-12-07T10:33:06.991329+00:00 [queued]>
[2022-12-07T10:33:08.506+0000] {taskinstance.py:1165} INFO - Dependencies all met for <TaskInstance: dag.task_1_0 manual__2022-12-07T10:33:06.991329+00:00 [queued]>
[2022-12-07T10:33:08.506+0000] {taskinstance.py:1362} INFO - 
--------------------------------------------------------------------------------
[2022-12-07T10:33:08.507+0000] {taskinstance.py:1363} INFO - Starting attempt 1 of 1
[2022-12-07T10:33:08.507+0000] {taskinstance.py:1364} INFO - 
--------------------------------------------------------------------------------
[2022-12-07T10:33:08.542+0000] {taskinstance.py:1383} INFO - Executing <Task(PythonOperator): task_1_0> on 2022-12-07 10:33:06.991329+00:00
[2022-12-07T10:33:08.548+0000] {standard_task_runner.py:55} INFO - Started process 690 to run task
[2022-12-07T10:33:08.555+0000] {standard_task_runner.py:82} INFO - Running: ['***', 'tasks', 'run', 'dag', 'task_1_0', 'manual__2022-12-07T10:33:06.991329+00:00', '--job-id', '1626', '--raw', '--subdir', 'DAGS_FOLDER/dag.py', '--cfg-path', '/tmp/tmp73xq6747']
[2022-12-07T10:33:08.556+0000] {standard_task_runner.py:83} INFO - Job 1626: Subtask task_1_0
[2022-12-07T10:33:08.652+0000] {task_command.py:376} INFO - Running <TaskInstance: dag.task_1_0 manual__2022-12-07T10:33:06.991329+00:00 [running]> on host ede3719a0239
[2022-12-07T10:33:08.861+0000] {taskinstance.py:1592} INFO - Exporting the following env vars:
AIRFLOW_CTX_DAG_OWNER=lofitravel
AIRFLOW_CTX_DAG_ID=dag
AIRFLOW_CTX_TASK_ID=task_1_0
AIRFLOW_CTX_EXECUTION_DATE=2022-12-07T10:33:06.991329+00:00
AIRFLOW_CTX_TRY_NUMBER=1
AIRFLOW_CTX_DAG_RUN_ID=manual__2022-12-07T10:33:06.991329+00:00
[2022-12-07T10:33:09.348+0000] {taskinstance.py:1851} ERROR - Task failed with exception
Traceback (most recent call last):
  File "/home/airflow/.local/lib/python3.7/site-packages/airflow/operators/python.py", line 175, in execute
    return_value = self.execute_callable()
  File "/home/airflow/.local/lib/python3.7/site-packages/airflow/operators/python.py", line 193, in execute_callable
    return self.python_callable(*self.op_args, **self.op_kwargs)
  File "/opt/airflow/dags/dag.py", line 24, in get_currencies_task
    value = obj.pair(ticker_from, ticker_to)#....#
  File "/opt/airflow/dags/dag.py", line 66, in pair
    return response.json()['response']['value']
TypeError: list indices must be integers or slices, not str
[2022-12-07T10:33:09.370+0000] {taskinstance.py:1406} INFO - Marking task as FAILED. dag_id=dag, task_id=task_1_0, execution_date=20221207T103306, start_date=20221207T103308, end_date=20221207T103309
[2022-12-07T10:33:09.390+0000] {standard_task_runner.py:105} ERROR - Failed to execute job 1626 for task task_1_0 (list indices must be integers or slices, not str; 690)
[2022-12-07T10:33:09.407+0000] {local_task_job.py:159} INFO - Task exited with return code 1
[2022-12-07T10:33:09.469+0000] {taskinstance.py:2623} INFO - 0 downstream tasks scheduled from follow-on schedule check
